Workbook

Sheet Lembar Monitoring
A1: LEMBAR MONITORING DAN EVALUASI MANAJEMEN RISIKO UNIT
A2: SATUAN PENGAWAS INTERNAL
A3: POLITEKNIK NEGERI MALANG
A5: UNIT | B5: : | C5: =VLOOKUP(J7,Kegiatan!$A$3:$K$717,2,TRUE) -> D-III Akuntansi PSDKU Kediri-1 | E5: PEMONEV | F5: : | G5: Usman Nurhasan, S.Kom., M.T. | J5: No Kegiatan
A6: KODE RISIKO | B6: : | E6: Tahun Anggaran KEGIATAN | F6: : | G6: 2025 | J6: 1 | K6: 2 | L6: 3 | M6: 4 | N6: 5 | O6: 6 | P6: 7 | Q6: 8 | R6: 9
A7: KEGIATAN | B7: : | C7: =VLOOKUP(J7,Kegiatan!$A$3:$K$717,3,TRUE) -> Focus Group Discussion Kurikulum Merdeka Belajar Kampus Merdeka (MBKM) - Lanjutan - D-III Akuntansi PSDKU Kediri | J7: 36 | K7: 0 | L7: 0 | M7: 0 | N7: 0 | O7: 0 | P7: 0 | Q7: 0
A8: PERNYATAAN RISIKO | B8: : | C8: =VLOOKUP(J7,Kegiatan!$A$3:$K$717,10,TRUE) -> Karena keterbatasan kemampuan SDM dalam mengembangkan kurikulum berbasis MBKM di Prodi D3 Akuntansi Kampus Kediri mungkin proses pengajaran berbasis kurikulum MBKM tidak maksimal, sehingga pengajaran berbasis kurikulum MBKM tidak berjalan
A9: LEVEL RISIKO | B9: : | C9: =VLOOKUP(J7,Kegiatan!$A$3:$K$717,7,TRUE) -> HIGH | E9: RISIKO RESIDUAL | F9: : | G9: Extreme
J10: 1. Apakah kegiatan tersebut sudah selesai di laksanakan ?
A11: PENGENDALIAN | D11: MITIGASI RISIKO | E11: KOMENTAR | J11: 2. Apakah bapak/ibu akan Menerima, Membagi atau Melimpahkan Risiko tersebut?
A12: =VLOOKUP(J7,Kegiatan!$A$3:$K$717,11,TRUE) -> Untuk mengatasi resiko yang mungkin terjadi, maka cara mengendalikan dampaknya adalah: mengikuti sosialisasi online atau menunggu kampus pusat untuk mengadakan sosialisasi tentang kurikulum merdeka belajar. | D12: Menerima Risiko | E12: 1. Sentralisasi Repositori Bukti: Buat penyimpanan digital terpusat dan berindeks untuk semua bukti pendukung. 2. Finalisasi LKPS & Cross-Check: perept penyelesaian draft Laporan Kinerja Program Studi (LKPS) dan lakukan verifikasi silang (cross-check) bahwa semua klaim di laporan didukung bukti yang tersedia. 3. Koordinasi Khusus Keuangan: Lakukan koordinasi intensif dengan Pihak Keuangan untuk mempercepat pencairan dana kegiatan yang hasilnya akan menjadi bukti kritis akreditasi. | J12: STRATEGI MITIGASI
J13: 3. Apa langkah-langkah mitigasi yang telah diterapkan untuk mengurangi dampak atau
J14: kemungkinan terjadinya risiko ?
J15: 4. Bagaimana efektivitas langkah mitigasi yang telah dilakukan sejauh ini?
D16: =IF(D12="Menerima Risiko","","Unit Penerima Risiko") | J16: 5. Mampukan langkah tersebut mengendalikan risiko shingga Resiko Residualnya bisa turun
J17: atau tetap sama
J18: 6. Apakah ada perubahan atau penambahan strategi mitigasi yang perlu dilakukan?
J19: PELAKSANAAN MITIGASI
D20: Status Konfirmasi | J20: 7. Apa langkah-langkah mitigasi yang telah diterapkan untuk mengurangi dampak atau
D21: - | J21: kemungkinan terjadinya risiko?
D22: - | J22: 8. Apakah ada perubahan atau penambahan strategi mitigasi yang perlu dilakukan?
D23: - | J23: MONITORING dan PENGENDALIAN
J24: 9. Bagaimana cara Anda memonitor perkembangan mitigasi risiko secara berkelanjutan?
J25: 10. Apakah pengendalian yang ada cukup efektif untuk menjaga agar risiko tetap terkendali?
G26: Malang, 22/09/ | H26: =G6 -> 2025 | J26: 11. Apakah semua pihak terkait sudah terlibat dan memahami tindakan mitigasi ini ?
C27: Unit. | G27: Pemonev | J27: EVALUASI KINERJA & KEBERHASILAN MITIGASI
J28: 11. Apa indikator yang digunakan untuk mengukur keberhasilan mitigasi risiko?
J29: 12. Apakah ada faktor yang belum teridentifikasi yang mempengaruhi efektivitas mitigasi?
J30: TINDAK LANJUT & PERBAIKAN
J31: 13. Apakah ada kebutuhan memperbarui / memperbaiki langkah mitigasi
G32: =G5 -> Usman Nurhasan, S.Kom., M.T. | J32: berdasarkan evaluasi yang ada?
G33: =IF(G32="Dr. Drs. Sumiadji, Ak., M.SA.","NIP. 196405121993031001",IF(G32="Usman Nurhasan, S.Kom., M.T.","NIP. 198909162014042001",IF(G32="Ir. Wahiddin, S.T., MT.IPM.ASEAN Eng.","NIP. 197312072003121001",IF(G32="Dr. Ir. Azam Muzakhim Imammuddin, M.T.","NIP. 196705041994031004",IF(G32="Dr. Atik Andhayani, S.E., MSA.","NIP. 197505032009032001",IF(G32="Lina Budiarti, S.E., M.M.","NIP. 198609232015041001",IF(G32="Drs. Mufid M.T.","NIP. 196408221994031001",IF(G32="Lis Diana Mustafa, S.T., M.T.","NIP. 197805052001122003")))))))) -> NIP. 198909162014042001 | J33: 14. Apa tindakan korektif yang perlu dilakukan
J34: untuk meningkatkan mitigasi risiko di masa mendatang?
A36: LEMBAR MONITORING DAN EVALUASI MANAJEMEN RISIKO UNIT
A37: SATUAN PENGAWAS INTERNAL
A38: POLITEKNIK NEGERI MALANG
A40: UNIT | B40: : | C40: =VLOOKUP(K42,Kegiatan!$A$3:$K$717,2,TRUE) -> #N/A | E40: PEMONEV | F40: : | G40: Usman Nurhasan, S.Kom., M.T. | J40: No Kegiatan
A41: KODE RISIKO | B41: : | E41: Tahun Anggaran KEGIATAN | F41: : | G41: 2025 | J41: 1 | K41: 2 | L41: 3 | M41: 4 | N41: 5 | O41: 6 | P41: 7 | Q41: 8 | R41: 9
A42: KEGIATAN | B42: : | C42: =VLOOKUP(K42,Kegiatan!$A$3:$K$717,3,TRUE) -> #N/A | J42: =J7 -> 36 | K42: =K7 -> 0 | L42: =L7 -> 0 | M42: =M7 -> 0 | N42: =N7 -> 0 | O42: =O7 -> 0 | P42: =P7 -> 0 | Q42: =Q7 -> 0 | R42: =R7 -> 0
A43: PERNYATAAN RISIKO | B43: : | C43: =VLOOKUP(K42,Kegiatan!$A$3:$K$717,10,TRUE) -> #N/A
...

Sheet Unit & Pemonev
B3: PEMONEV | E3: UNIT
B4: NO | C4: NAMA | E4: NO | F4: NAMA UNIT
B5: Q | E5: 1
B6: 1 | C6: Dr. Drs. Sumiadji, Ak., M.SA. | E6: 2 | F6: - DEWAS
B7: 2 | C7: Usman Nurhasan, S.Kom., M.T. | E7: 3 | F7: - Senat
B8: 3 | C8: Ir. Wahiddin, S.T., MT.IPM.ASEAN Eng. | E8: 4 | F8: - WADIR I
B9: 4 | C9: Dr. Ir. Azam Muzakhim Imammuddin, M.T. | E9: 5 | F9: - WADIR II
B10: 5 | C10: Dr. Atik Andhayani, S.E., MSA. | E10: 6 | F10: - WADIR III
B11: 6 | C11: Lina Budiarti, S.E., M.M. | E11: 7 | F11: - WADIR IV
B12: 7 | C12: Drs. Mufid M.T. | E12: 8 | F12: - BAK
B13: 8 | C13: Lis Diana Mustafa, S.T., M.T. | E13: 9 | F13: - BPKU
E14: 10 | F14: - P2MPP
E15: 11 | F15: - P3M
E16: 12 | F16: - SPI
E17: 13 | F17: - UPA Bahasa
E18: 14 | F18: - UPA LUK
E19: 15 | F19: - UPA PKK
E20: 16 | F20: - UPA PP
E21: 17 | F21: - UPA Perpustakaan
E22: 18 | F22: - UPA TIK
E23: 19 | F23: - Jurusan Adiministrasi Niaga
E24: 20 | F24: - D-IV Pengelolaan Arsip dan Rekaman Informasi
E25: 21 | F25: - D-IV Usaha Perjalanan Wisata
... E72: 68 | F72: - PSDKU Kota Pamekasan

Sheet Kegiatan
B1: REKAP IDENTIFIKASI DAN ANALISIS RISIKO SELURUH UNIT TAHUN 2025
B3: Nama Unit & Kode | C3: Usulan Kegiatan | D3: Nilai Usulan | E3: Skor Probabilitas | F3: Skor Dampak | G3: Tingkat Risiko | H3: SPIP | I3: Uraian Dampak | J3: Pernyataan Risiko | K3: Pengendalian
A4: 1 | B4: D-III Teknik Telekomunikasi-1 | C4: FGD dan Inisiasi kerja sama dalam pelaksanaan PKL dan MBKM - D-III Teknik Telekomunikasi | D4: 15790000 | E4: 5 | F4: 5 | G4: EXTREME | I4: Program studi kesulitan untuk mendapatkan mitra dalam upaya meingkatkan keikutsertaan MBKM bagi mahasiswa | J4: Karena kurangnya kepercayaan industri terhadap kompetensi mahasiswa mungkin tidak banyak industri telekomuniikasi yang dapat secara langsung melibatkan mahasiswa melalui MBKM sehingga kurangnya kerjasama prodi dengan mitra untuk menunjang MBKM | K4: Membuat database PT sehingga dapat memetakan mitra/industri yang telah dan belum menyusun dokumen kerjasama dengan Polinema serta menambahkan klausul penelitian dosen dan mahasiswa dalam dokumen kerjasama yang telah/akan dibuat
A5: 2 | B5: D-III Teknik Telekomunikasi-2 | C5: FGD dan Inisiasi Kerjasama dengan Kampus LN - D-III Teknik Telekomunikasi | D5: 8320000 | E5: 5 | F5: 5 | G5: EXTREME | I5: Program studi kesulitan untuk mendapatkan mitra dalam upaya meingkatkan keikutsertaan MBKM bagi mahasiswa | J5: Karena kurangnya kepercayaan industri terhadap kompetensi mahasiswa mungkin tidak banyak industri telekomuniikasi yang dapat secara langsung melibatkan mahasiswa melalui MBKM sehingga kurangnya kerjasama prodi dengan mitra untuk menunjang MBKM | K5: Membuat database PT sehingga dapat memetakan mitra/industri yang telah dan belum menyusun dokumen kerjasama dengan Polinema serta menambahkan klausul penelitian dosen dan mahasiswa dalam dokumen kerjasama yang telah/akan dibuat
A6: 3 | B6: D-IV Jaringan Telekomunikasi Digital-6 | C6: FGD dan Inisiasi Kerjasama dengan Industri dalam Pelaksanaan MBKM - D-IV Jaringan Telekomunikasi Digital - D-IV Jaringan Telekomunikasi Digital | D6: 28817500 | E6: 5 | F6: 5 | G6: EXTREME | I6: Program studi kesulitan untuk mendapatkan mitra dalam upaya meingkatkan keikutsertaan MBKM bagi mahasiswa | J6: Karena kurangnya kepercayaan industri terhadap kompetensi mahasiswa mungkin tidak banyak industri telekomuniikasi yang dapat secara langsung melibatkan mahasiswa melalui MBKM sehingga kurangnya kerjasama prodi dengan mitra untuk menunjang MBKM | K6: Membuat database PT sehingga dapat memetakan mitra/industri yang telah dan belum menyusun dokumen kerjasama dengan Polinema serta menambahkan klausul penelitian dosen dan mahasiswa dalam dokumen kerjasama yang telah/akan dibuat
A7: 4 | B7: D-IV Manajemen Pemasaran-6 | C7: Peningkatan Kerjasama Luar Negeri Prodi D-IV Manajemen Pemasaran | D7: 21845000 | E7: 5 | F7: 5 | G7: EXTREME | I7: 1. Tidak mempunyai kerjasama dengan mitra luar negeri; 2. Peningkatan daya saing global tidak terwujud. | J7: Karena terbatasnya jejaring luar negeri dalam mendukung pembelajaran dan pengembangan internasional, mungkin kurangnya pendekatan kepada mitra luar negeri, sehingga Peningkatan kerjasama luar negeri Prodi D-IV Manajemen Pemasaran tidak berjalan | K7: 1. Melakukan inisiasi kerjasama dengan PT luar negeri. 2. Melakukan perencanaan kegiatan yang mendukung kegiatan kerjasama luar negeri.
A8: 5 | B8: D-IV Manajemen Pemasaran-9 | C8: Rekonstruksi dan Ujicoba Kurikulum Prodi D-IV Manajemen Pemasaran | D8: 13821000 | E8: 5 | F8: 5 | G8: EXTREME | I8: 1.Tidak terlaksananya kegiatan rekonstruksi dan uji coba kurikulum Prodi D-IV Manajemen Pemasaran dengan baik; 2. Tidak adanya kurikulum yang selaras dengan dunia usaha dunia industri. | J8: Karena tidak memiiliki pedoman rekonstruksi dan ujicoba kurikulum yang update sesuai dunia industri, mungkin Terbatasnya data dan informasi rekonstruksi dan ujicoba kurikulum Prodi D-IV Manajemen Pemasaran, sehingga Rekonstruksi dan ujicoba kurikulum Prodi D-IV Manajemen Pemasaran tidak berjalan | K8: Melaksanakan monitoring tepat waktu. Memberikan sosialisasi lebih awal tentang hasil kurikulum. Menyusun kurikulum tepat waktu. Menyusun pedoman kurikulum program studi. Melakukan ujicoba kurikulum.
A9: 6 | B9: D-IV Manajemen Pemasaran-10 | C9: Pembelajaran PBL Semester Ganjil (Pelatihan Table Manner, Praktek E-Commerce & Marketing Event Project) - D-IV Manajemen Pemasaran | D9: 40887000 | E9: 5 | F9: 5 | G9: EXTREME | I9: 1. Pembelajaran PBL Semester Ganjil tidak berjalan sesuai dengan perencanaan; 2. Capaian pembelajaran yang diharapkan tidak dapat terpenuhi. | J9: Karena kurangnya koordinasi antar dosen dalam pelaksanaan pembelajaran semester ganjil, mungkin pelaksanaan pembelajaran PBL tidak sesuai dengan jadwal yang ditetapkan, sehingga Pembelajaran PBL semester Ganjil (pelatihan Table Manner, Praktek E-Commerce & Marketing Event Project) tidak berjalan | K9: Melakukan koordinasi antar dosen dalam pelaksanaan pembelajaran semester ganjil. Memastikan RPS mata kuliah telah tersusun awal perkuliahan. Menjalankan program pembelajaran sesuai dengan yang direncanakan.
A10: 7 | B10: D-IV Manajemen Pemasaran-11 | C10: Pembelajaran PBL Semester Genap (Digital Marketing Project, Pameran Produk Kewirausahaan, dan Riset Pemasaran) - D-IV Manajemen Pemasaran | D10: 44084580 | E10: 5 | F10: 5 | G10: EXTREME | I10: 1. Pembelajaran PBL Semester Genap tidak berjalan sesuai dengan perencanaan; 2. Capaian pembelajaran yang diharapkan tidak dapat terpenuhi. | J10: Karena kurangnya koordinasi antar dosen dalam pelaksanaan pembelajaran semester genap, mungkin pelaksanaan pembelajaran PBL tidak sesuai dengan jadwal yang ditetapkan, sehingga Pembelajaran PBL semester genap (Digital Marketing Project, Pameran Produk Kewirausahaan, dan Riset Pemasaran) - D-IV Manajemen Pemasaran tidak berjalan | K10: Melakukan koordinasi antar dosen dalam pelaksanaan pembelajaran semester genap. Memastikan RPS mata kuliah telah tersusun awal perkuliahan. Menjalankan program pembelajaran sesuai dengan yang direncanakan.
A11: 8 | B11: D-IV Usaha Perjalanan Wisata-3 | C11: Penguatan Kerjasama Prodi dengan Mitra Industri Pariwisata Bandung - D-IV Usaha Perjalanan Wisata | D11: 12760000 | E11: 5 | F11: 5 | G11: EXTREME | I11: Kurangnya informasi terkait industri sasaran kerjasama dan mundurnya jadwal kegiatan kunjungan industri, proses monitoring kurang maksimal | J11: Karena tidak memiliki data base industri sasaran dan industri tempat magang, mungkin industri sasaran yang sesuai untuk pengembangan kerjasama tidak ada dan industri tempat monitoring pelaksanaan magang tidak siap sehingga kunjungan industri pariwisata untuk pengembangan kerjasama dan monitoring pelaksanaan magang tidak berjalan | K11: Membuat database industri sasaran pengembangan kerjasama dan industri tempat magang
A12: 9 | B12: D-IV Usaha Perjalanan Wisata-4 | C12: Peningkatan Kerjasama Program Studi Melalui Praktikum Mahasiswa Pada Mata Kuliah Akomodasi Perhotelan Dan Dan Restoran Ke Hotel Grand Mercure Malang Mirama - D-IV Usaha Perjalanan Wisata | D12: 4095000 | E12: 5 | F12: 5 | G12: EXTREME | I12: proses kegiatan praktikum tidak maksimal dan peserta tidak mendapatkan ilmu yang bisa digunakan pada dunia kerja | J12: karena tidak ada mahasiswa D4 UPW yang melakukan praktikum mahasiswa pada mata kuliah Akomodasi Perhotelan dan Restoran di industri secara riil mungkin karena tidak adanya praktisi dan pendamping minat kegiatan mahasiswa sehingga praktikum tersebut tidak berjalan | K12: melakukan persiapan secara matang untuk mencari narasumber yang sesuai dengan tema dan memiliki pengalaman menjadi pendamping pada program praktikum atau sejenis
A13: 10 | B13: D-IV Usaha Perjalanan Wisata-6 | C13: Workshop Ticketing and Reservation System - D-IV Usaha Perjalanan Wisata | D13: 4595000 | E13: 5 | F13: 5 | G13: EXTREME | J13: Karena terbatasnya industri atau institusi yang membuka program pelatihan ticketing dan reservation yang selaras dengan kebutuhan prodi D4 UPW dan mahasiswa tidak menyesuaikan kurikulum , mungkin karena terhambatnya proses penyusunan pedoman kurikulum khususnya ticketing dan reservation sehingga Workshop Ticketing and Reservation System - D-IV Usaha Perjalanan Wisata tidak berjalan dengan sesuai seperti yang diharapkan | K13: Sosialisasi kurikulum MK Ticketing dan Reservation dengan metode PBL sebelum kegiatan kepada seluruh dosen homebase D4 UPW
A14: 11 | B14: D-IV Usaha Perjalanan Wisata-7 | C14: Forum Group Discussion Tentang Penyusunan Kurikulum Berbasis OBE dengan Industri - D-IV Usaha Perjalanan Wisata | D14: 6455000 | E14: 5 | F14: 5 | G14: EXTREME | I14: Lamanya waktu yang diperlukan untuk telaah dan persiapan draft bahan ajar berbasis OBE | J14: Karena terbatasnya industri yang membuka program MBKM yang selaras dengan Prodi D4 UPW dan mahasiswa tidak menyesuaikan kurikulum dalam mengajukan MBKM mungkin karena terhambatnya proses penyusunan pedoman kurikulum berbasis OBE dengan industri di kantor pusat sehingga FGD tentang Penyusunan Kurikulum Berbasis OBE dengan Industri D-IV Usaha Perjalanan Wisata tidak berjalan sesuai yg seperti diharapkan | K14: Sosialisasi pedoman pembelajaran berbasis OBE sebelum kegiatan kepada seluruh dosen homebase D$ UPW
A15: 12 | B15: Jurusan Teknik Elektro-3 | C15: Inisiasi Kerjasama Dengan Mitra Potensial Dalam Bentuk Focus Group Discussion di Jurusan Teknik Elektro | D15: 17500000 | E15: 5 | F15: 5 | G15: EXTREME | I15: Jurusan Teknik Elektro tidak memiliki mitra untuk dapat meningkatkan kerjasama industri | J15: Karena kurangnya kepercayaan industri terhadap kompetensi Jurusan Teknik Elektro mungkin tidak banyak industri telekomuniikasi yang dapat secara langsung menjalin kerjasama melalui sehingga kurangnya kerjasama prodi dengan mitra untuk menunjang MBKM | K15: Membuat database PT sehingga dapat memetakan mana yang belum MoU dan yang sudah selain itu membuat perjanjian ditambahkan dengan penelitian dosen dan mahasiswa
A16: 13 | B16: P3M-15 | C16: PENELITIAN DIPA KOMPETISI 2025 - P3M | D16: 5440155000 | E16: 5 | F16: 5 | G16: EXTREME | I16: Menggangu ketercapaian kinerja dosen dan IKU Polinema | J16: KARENA terlambat dalam menentukan skema penelitian MUNGKIN sosialisasi perubahan aturan terlambat disampaikan kepada peneliti SEHINGGA Penelitian DIPA KOMPTESI 2025 P3M tidak dapat dilaksanakan | K16: Perlu dilakukan penyusunan panduan dan skema penelitian sebagai petunjuk teknis pelaksanaan. Perlu dilakukan sosialisasi panduan dan penentuan penjadwalan seleksi hingga pelaporan pelaksanaan kepada seluruh civitas akademika Polinema. Perlu dilakukannya monitoring dan koordinasi pelaksanaan kegiatan sehingga luaran penelitian dapat tercapai
A17: 14 | B17: UPA Pengembangan Karir dan Kewirausahaan-4 | C17: INKUBASI WIRAUSAHA MAHASISWA 2025 - UPA Pengembangan Karir dan Kewirausahaan | D17: 77080000 | E17: 5 | F17: 5 | G17: EXTREME | I17: terjadi kemunduran pelaksanaan kegiatan penampingan usaha dari tenant inkubasi. | J17: karena adanya keterlambatan pencairan bantuan modal usaha dan tidak tepat waktu, sehingga menyebabkan kendala di keseluruhan proses pendampingan terutama mundurnya jadwal pelaksanaan kegiatan. | K17: membuat jadwal pelaksanaanan kegiatan, dan kepatuhan terhadap jadwal yang di buat. pencairan modal usaha tepat waktu sehingga membantu proses kelancaran pendampingan dan kegiatan produksi mahasiswa wirausaha.
A18: 15 | B18: UPA Pengembangan Karir dan Kewirausahaan-10 | C18: Program Mahasiswa Wirausaha (PMW) Polinema 2025 - UPA Pengembangan Karir dan Kewirausahaan | D18: 302568000 | E18: 5 | F18: 5 | G18: EXTREME | I18: Karena KETERLAMBATAN DAN SULITNYA PROSES PENCAIRAN BANTUAN MODAL USAHA , sehingga menyebabkan resiko sangat terlambat dalam proses pendampingan dan produksi, yang mengakibatkan mundurnya jadwal kegiatan lainnya sebagai rangkaian kegiatan PMW. ada beberapa kegiatan lain yang pelaksanaan nya hanya bisa dilakukan setelah tenant PMW berjalan proses produksinya, sehingga jika pencairan modal usaha ini terlambata akan menghambat pelaksanaan kegiatan lainnya. perlu di pahami bahwa wirausaha adalah menjalankan usaha yang membutuhkan modal untuk proses produksinya. periode waktu usaha yang seharusnya 1 tahun juga sangat terbatas, karena efektif operasional usahanya hanya 6 bulan (jika pencairan bantuan modal di bulan mei 2025). hal ini sebenar nya kurang efektif untuk progres sebuah usaha. oleh karena itu kami berharap bantuan untuk ketepatan jawal pelaksanaan program. | J18: Karena KETERLAMBATAN DAN SULITNYA PROSES PENCAIRAN BANTUAN MODAL USAHA , sehingga menyebabkan resiko sangat terlambat dalam proses pendampingan dan produksi, yang mengakibatkan mundurnya jadwal kegiatan lainnya sebagai rangkaian kegiatan PMW. | K18: 1. penjadwalan dan pelaksanaan kegiatan sesuai dengan time line yang sudah di tetapkan. 2. koordinasi dengan bagian keuangan dan tim kerja terkait ketepatan waktu pencairan bantuan modal usaha mahasiswa. 3. komunikasi yang baik agar pelaksanaan kegiatan bisa dilakukan dengan baik, efektif, tepat waktu , dan memberikan manfaat bagi mahasiswa wirausaha.
A19: 16 | B19: WADIR II-10 | C19: PEMBANGUNAN GEDUNG DAN BANGUNAN PENDUKUNG PEMBELAJARAN - BLU | D19: 40556300000 | E19: 5 | F19: 5 | G19: EXTREME | I19: Melakukan persiapan data dukung tender secara lengkap dan lebih awal, dan pendampingan proses oleh BPKP Jawa Timur dan Kejaksaan Tinggi Negeri | J19: Karena Data dukung penting untuk pengadaan tidak segera tersedia mungkin Kelengkapan berkas pengadaan terlambat sehingga Pembangunan Gedung dan Bangunan Pendukung Pembelajaran tidak selesai. | K19: Adanya pendampingan dari pihak BPKP Jawa Timur dan Kejaksaan Tinggi Negeri agar pembangunan gedung dan bangunan pendukung pembelajaran dapat selesai tepat waktu.
A20: 17 | B20: WADIR II-25 | C20: PEMBANGUNAN GEDUNG DAN BANGUNAN PENDUKUNG PEMBELAJARAN SBSN - RM - WADIR II | D20: 87468000000 | E20: 5 | F20: 5 | G20: EXTREME | I20: Melakukan persiapan data dukung tender secara lengkap dan lebih awal, dan pendampingan proses oleh BPKP Jawa Timur dan Kejaksaan Tinggi Negeri | J20: Karena Data dukung penting untuk pengadaan tidak segera tersedia mungkin Kelengkapan berkas pengadaan terlambat sehingga Pembangunan Gedung dan Bangunan Pendukung Pembelajaran tidak selesai. | K20: Adanya pendampingan dari pihak BPKP Jawa Timur dan Kejakaan Tinggi Negeri agar pembangunan gedung dan bangunan pendukung pembelajar dapat selesai tepat waktu.
A21: 18 | B21: BPKU-3 | C21: Pembinaan Dan Peningkatan Kualitas Pegawai Dalam Bidang Wawasan Kebangsaan | D21: 204269000 | E21: 4 | F21: 4 | G21: HIGH | I21: Tidak terlaksananya upacara dalam rangka peringatan Dies Natalis dan hari besar nasional | J21: Karena kurangnya koordinasi internai Pokja Protokoler dengan jajaran Pimpinan, mungkin tidak terdapat informasi terkait Pembinaan dan Peningkatan Kualitas Pegawai dalam Bidang Wawasan Kebangsaan sehingga Pembinaan dan Peningkatan Kualitas Pegawai dalam Bidang Wawasan Kebangsaan tidak berjalan | K21: Melaksanakan koordinasi dengan jajaran Pimpinan terkait upacara peringatan Dies Natalis dan hari besar nasional serta mencari informasi terkait pedoman pelaksanaan upacara dengan protokol kementerian.
A22: 19 | B22: BPKU-6 | C22: Pameran untuk keikutsertaan Promosi | D22: 122758000 | E22: 4 | F22: 4 | G22: HIGH | I22: Tidak dapat mengikuti pameran pendidikan yang mengakibatkan Menurunnya kuantitas pendaftarSPMB | J22: Karena masih dalam penyusunan anggaran indikatif mungkin kegiatan pameran dilaksanakan di awal tahun ketika belum ada anggaran dan Anggaran belum ditetapkan sehingga Pameran Pendidikan di Wilayah Jawa Timur mengalami kesulitan | K22: Melakukan koordinasi dengan pimpinan terkait mekanisme penggunaan anggaran di awal tahun sebelum anggaran tahun berjalan ditetapkan Melakukan sosialisasi PMB melalui media sosial resmi POLINEMA, website, dan jaringan alumni sekolah
A23: 20 | B23: D-III Teknik Listrik-2 | C23: Kolaborasi Riset Mahasiswa dan Dosen serta pembinaan mahasiswa berprestasi - D-III Teknik Listrik | D23: 47600000 | E23: 4 | F23: 5 | G23: HIGH | I23: menurunya persentase mahasiswa yang merahih prestasi | J23: Karena Tidak ada SDM untuk koordinasi info berkala terkait lomba kepada mahasiswa mungkin minat mahasiswa untuk ikut serta lomba di tingkat nasional menjadi berkurang sehingga Tidak terdapatnya Peningkatan kualitas mahasiswa melalui keikutsertaan dalam lomba | K23: Memberikan informasi-informasi dan pemndampingan ke mahasiswa berkaitan dengan lomba-lomba
A24: 21 | B24: D-III Teknik Listrik-9 | C24: Pesiapan Proses Audit Mutu Internal (AMI) - D-III Teknik Listrik | D24: 17240000 | E24: 4 | F24: 5 | G24: HIGH | I24: menurunnya jumlah: (1) Jumlah mahasiswa yang terlibat dalam kegiatan penelitian; (2) Jumlah mahasiswa yang terlibat dalam kegiatan PkM; (3) Jumlah prodi terakreditasi Unggul / A. | J24: Karena Tidak adanya database untuk mendukung penyusunan Dokumen yang dibutuhkan untuk Audit Mutu Internal (AMI) mungkin tidak ada SDM untuk menyusun dokumen sehingga tidak tersedianya dokumen kelengkapan audit | K24: Dengan meunjuk tim khusus untuk melakukan pengumpulan data dukung secara terorganisir dan termonitor sehingga memudahkan penyusunan dokumen AMI serta memberikan workshop dan pendampingan dalam AMI
A25: 22 | B25: D-III Teknik Elektronika-1 | C25: Pelaksanaan Monitoring Evaluasi Pembelajaran Semester Ganjil - D-III Teknik Elektronika | D25: 11312000 | E25: 4 | F25: 5 | G25: HIGH | I25: Tidak adanya evaluasi proses belajar mengajar sehingga kekurangan dapat terulang di seriap tahun; Proses layanan pembelajaran kurang maksimal | J25: Karena tidak adanya koordinasi untuk menyusun panduan monitoring pelaksanaan belajar mengajar mungkin tidak ada panduan dalam melakukan monitoring proses belajar mengajar sehingga tidak terdapatnya monitoring pelaksanaan belajar mengajar, dari UTS, UAS dan yudisium. | K25: Membuat tim untuk membentuk SOP, membuat SOP untuk monitoring pembelajaran dengan pengawasan dari kps
... A184: 181 | B184: BAK-6 | C184: Workshop Tata Kelola Operasional dan Maintenance Aplikasi Help Akademik - BAK | D184: 12111000 | E184: 3 | F184: 5 | G184: MIDDLE | I184: Terbengkalainya layanan kepada mahasiswa melalui aplikasi help akademik; Memperlambat layanan kepada mahasiswa dengan offline | J184: Karena pelayanan akademik dilakukan offline mengingat aplikasi yang dioperasikan mungkin belum mendapat kepastian untuk dapat dilaksanakan sesuai kebijakan SI terbaru sehingga operasional dan maintenance aplikasi help akademik belum dapat dilanjutkan | K184: Kebijakan sistem informasi institusi diharapkan dapat mengakomodir sistem lain yang sudah berjalan dengan baik untuk efektivitas pelayanan kepada mahasiswa
A185: 182 | B185: BPKU-4 | C185: Digitalisasi Arsip Surat Keputusan dan Peraturan DIrektur | D185: 40000000 | E185: 3 | F185: 4 | G185: MIDDLE
A186: 183 | B186: BPKU-7 | C186: Pelatihan Keselamatan, Kesehatan Kerja & Lingkungan (K3L) Politeknik Negeri Malang | D186: 35000000 | E186: 3 | F186: 4 | G186: MIDDLE | I186: Risiko kecelakaan kerja dapat terjadi apabila para pegawai yang bertanggungjawab di bidang K3L tidak memahami prinsip-prinsip dan tata cara pelaksanaan Keselamatan, Kesehatan Kerja dan Lingkungan. | J186: Risiko kecelakaan kerja dapat terjadi apabila para pegawai yang bertanggungjawab di bidang K3L tidak memahami prinsip-prinsip dan tata cara pelaksanaan Keselamatan, Kesehatan Kerja dan Lingkungan. | K186: Melaksanakan pelatihan K3L dan melengkapi sarana prasarana penunjang K3L
A187: 184 | B187: BPKU-16 | C187: PERENCANAAN DAN MONEV: Rapat Kerja Program dan Anggaran Definitif 2025 - BPKU | D187: 141185000 | E187: 3 | F187: 5 | G187: MIDDLE | I187: Rapat Kerja Penyusunan Program dan Anggaran Indikatif tahun 2025 POLINEMA yang tidak berjalan dengan baik dapat berpengaruh terhadap ketepatan waktu penetapan pagu definitif institusi | J187: Rapat Kerja Penyusunan Program dan Anggaran Indikatif tahun 2025 Polinema merupakan kegiatan rutin untuk memastikan kualitas perencanaan dan penganggaran di Polinema tersusun dengan baik. Tidak terlaksananya Rapat Kerja Penyusunan Program dan Anggaran Indikatif tahun 2025 Polinema dapat mempengaruhi kualitas perencanaan program dan anggaran tahun 2025 serta menghambat ketercapaian indikator Kinerja Utama dan target kinerja institusi. | K187: 1) Meningkatkan kapasitas SDM; 2.) Menyusun perencanaan yang sesuai dengan prosedur dan kaidah keuangan negara; 3.) Penetapan pagu definitif tepat waktu sebagai acuan pelaksanaan program dan kegiatan
A188: 185 | B188: BPKU-20 | C188: Evaluasi Capaian Kinerja Program dan Anggaran Tahun Anggaran 2025 | D188: 86338000 | E188: 3 | F188: 5 | G188: MIDDLE | I188: Pelaksanaan kegiatan EPA tdk berjalan secara optimal | J188: Karena pelaksanaan kegiatan ini membutuhkan narasumber yang dari Kementerian mungkin akan terkendala pada jadwal narasumber yang kompeten dibiudang monev anggaran sehingga kegiatan EPA tdk berjalan dengan baik | K188: pelaksanaan kegiatan ini membutuhkan narasumber yang dari Kementerian Keuangan perlu adanya koordinasi yang baik agar pelaksanaan EPA dapat berjalan dengan baik
A189: 186 | B189: BPKU-24 | C189: Penyusunan Dokumen Pola Karir Pegawai Politeknik Negeri Malang untuk ASN Dosen dan Tenaga Kependidikan | D189: 11780000 | E189: 3 | F189: 4 | G189: MIDDLE | I189: Jika Kegiatan Pola karir tidak terlaksana maka Dokumen Pola Karir tidak dapet terselesaikan, dan jika tidak ada dokumen Pola Karir maka penataan dan jenjang karir pegawai tidak memiliki pedoman | J189: Apabila dokumen pola karier tidak tersusun pada tahun 2025 maka urutan penempatan dan/atau perpindahan PNS dalam dan antar posisi di setiap jenis Jabatan di lingkungan Polinema akan terkendala dan tidak memiliki dasar acuan yang tepat. | K189: Melaksanakan koordinasi dan timeline penyusunan dokumen pola karier agar dokumen pol karier dapat terselesaikan tepat waktu pada tahun 2025
A190: 187 | B190: BPKU-25 | C190: Penyusunan Dokumen Peta Jalan Pengembangan Kompetensi Pegawai Tenaga Kependidikan yang disesuaikan dengan Renstra Polinema | D190: 12500000 | E190: 3 | F190: 4 | G190: MIDDLE | I190: Kegiatan penyusunan Dokumen Peta Jalan tidak terlaksana, sehingga dapat menyebabkan penataan pegawai dan jenjang karir pegawai tidak memiliki pedoman | J190: Apabila kegiatan penyusunan Peta Jalan Pengembangan Kompetensi Pegawai Tenaga Kependidikan tidak terlksana, maka Polinema tidak memiliki dokumen Peta Jalan Pengembangan Kompetensi Pegawai Tenaga Kependidikan sebagai pedoman penataan jenjang karir pegawai. | K190: Melaksanakan koordinasi dan penyusunan timeline agar target penyusunan dokumen Peta Jalan Pengembangan Kompetensi Pegawai Tenaga Kependidikan dapat tercapai sesuai rencana
A191: 188 | B191: BPKU-28 | C191: Workshop Peningkatan Pengelolaan Kearsipan | D191: 9300000 | E191: 4 | F191: 3 | G191: MIDDLE | I191: Dengan pelaksanaan workshop pengelolaan kearsipan di harapkan layanan surat menyurat di masing-masing jurusan, unit dan bagian dapat lebih berjalan dengan baik | J191: Karena kurangnya data nara sumber yang memiliki kompetensi sesuai dengan yang dibutuhkan mungkin Workshop pengelolaan kearsipan belum dapat dapat dilaksanakan dengan baik sehingga pengelolaan kearsipan belum dapat di laksanakan secara opti mal | K191: Diperlukan layanan yang baik dalam surat menyurat dan pengarsipan
A192: 189 | B192: BPKU-29 | C192: Workshop Sinkronisasi Data di SIMPEG, SINTA, SINERJA dan SIDAKIN Politeknik Negeri Malang | D192: 8980000 | E192: 4 | F192: 3 | G192: MIDDLE | I192: Dapat mengakibatkan tidak tercapainya kinerja Direktur yang telah di targetkan dalam masing-masing IKU sehingga tidak diterimanya reward anggaran kinerja | J192: Ketidaksesuaian data pada aplikasi SIMPEG, SINTA dan SISTER akan terintegrasi pada penilaian kinerja di aplikasi SIDAKIN yang dilaksanakan pada akhir tahun. Data pada aplikasi SIDAKIN yang tidak valid mengakibatkan tidak tercapainya kinerja Direktur yang telah di targetkan dalam masing-masing IKU | K192: pengisian dan update data secara rutin pada apliaksi SIMPEG dan SISTER sehingga data valid
A193: 190 | B193: BPKU-30 | C193: Pelatihan Peningkatan Layanan Prima Bagi Tenaga Kependidikan dalam upaya meningkatkan motivasi dan kualitas layanan di Jajaran BPKU Polinema - BPKU | D193: 91456000 | E193: 3 | F193: 5 | G193: MIDDLE | I193: Tidak terlaksananya kegiatan pemberian motivasi untuk peningkatan kualitas layanan berdapak pada kurangnya motivali layanan prima yang berdampak pada kurang berkualitasnya layanan serta layanan tidak dapat dipercaya. | J193: Karena kurangnya data nara sumber yang memiliki kompetensi sesuai dengan yang dibutuhkan mungkin pelatihan peningkatan layanan prima bagi tenaga kependidikan tidak dapat dilaksanakan dengan baik sehingga layanan tidak dapat dipercaya dan kurang berkualitas. | K193: Diperlukan adanya motivasi dan kualitas layanan terbaik dalam menjalankan tugas di jajaran BPKU
A194: 191 | B194: D-II Perangkat Piranti Lunak Situs-2 | C194: Sinkronisasi Dokumen Kurikulum dengan Capaian - D-II Perangkat Piranti Lunak Situs - D-II Perangkat Piranti Lunak Situs | D194: 8839000 | E194: 4 | F194: 3 | G194: MIDDLE | I194: 1. Data yang diperoleh kurang sesuai 2. Terhambatnya kegiatan penyusunan LKPS dan persiapan Akreditasi | J194: Karena adanya kekurangan data/sumber data yang dikumpulkan, mungkin data yang disampaikan kurang akurat/up to date, sehingga penyusunan LKPS dan persiapan Akreditasi D2 PLS menjadi terhambat. | K194: 1. Memastikan bahwa petugas/tim yang menangani penyusunan LKPS dan persiapan Akreditasi D4 dapat mengumpulkan data sejak awal secara bertahap dan sistematis 2. Memastikan data yang dikumpulkan sudah data terbaru/up to date
A195: 192 | B195: D-III Teknik Listrik-8 | C195: Penyempurnaan Dokumen Kurikulum | D195: 15550000 | E195: 4 | F195: 3 | G195: MIDDLE | I195: tidak adanya Prodi yang telah memiliki kurikulum berbasis DUDI yang telah disusun dan diimplementasikan di kampus | J195: Karena tidak ada acuan (SOP) untuk menyusun Kurikulum, Silabus Berbasis DUDI mungkin tidak ada SDM untuk menyusun Kurikulum, Silabus Berbasis DUDI sehingga Tidak tersedianya Kurikulum, Silabus dan penyusunan kurikulum berbasis DUDI | K195: melakukan workshop serta pendampingan pembuatan kurikulum yang sesuai dengan DUDI
A196: 193 | B196: D-III Teknik Mesin-3 | C196: Monitoring dan Supervisi Pelaksanaan Magang Industri Mahasiswa Program Studi D3 Teknik Mesin | D196: 29851000 | E196: 3 | F196: 5 | G196: MIDDLE | I196: Masukan terhadap perbaikan kurikulum serta rencana pelaksanaan magang/PKL mahasiswa dengan berlakunya kurikulum 4+1+1 (1 smstr PKL di industri) tidak maksimal tersampaikan. | J196: Karena kurangnya komunikasi dan perencanaan jadwal kunjungan yang sesuai mungkin tidak banyak perusahaan yang menerima mahasiswa PKL dapat dikunjungi untuk kegiatan monev sehingga masukan terkait pelaksanaan PKL dan masukan terhadap perbaikan kurikulum belum dapat memperoleh feedback. | K196: Perlu ditingkatkan komunikasi dan perencanaan yang matang terkait rencana monev, supervisi dan kunjungan ke industri tempat mahasiswa PKL sehingga target kegiatan dapat tercapai
A197: 194 | B197: D-III Teknik Telekomunikasi-7 | C197: Pengadaan Alat Pendidikan Penunjang Pembelajaran - D-III Teknik Telekomunikasi | D197: 99073750 | E197: 3 | F197: 5 | G197: MIDDLE | I197: Menurunnya jumlah alat/fasilitas/sarpra yang telah dipelihara dan berfungsi dengan baik | J197: Karena tidak adanya SDM yang dapat mencari alat praktikum dengan kandungan TKDN serta menyusun HPS ditingkat prodi mungkin lamanya waktu yang diperlukan untuk mencari alat praktikum dengan TKDN serta penyusunan HPS sehingga tidak tersedia alat praktikum yang memadai | K197: Menyertakan tim teknis perumus HPS dalam penyusunan HPS untuk memenuhi TKDN mengikuti database yang ada dan minimum 40% dan monitoring proses pengadaan
... A541: 538 | B541: S-2 Sistem Informasi Akuntansi-4 | C541: PENINGKATAN KERJASAMA PROGRAM STUDI MELALUI FGD DENGAN INDUSTRI PRODI S-2 SISTEM INFORMASI AKUNTANSI | D541: 7755000 | E541: 3 | F541: 3 | G541: LOW | I541: tidak memiliki database industri yang akan dikunjungi Kegiatan tidak berjalan sesuai waktu yang telah direncanakan di awal (di simkeu) | J541: Karena objek kunjungan merupakan mitra industri, waktu perlu menyesuaikan dengan kesibukan mitra industri, dan tidak memiliki database industri yang akan dikunjungi mungkin Industri Sasaran yang sesuai untuk Pengembangan Kerjasama belum siap untuk dikunjungi sehingga kegiatan tidak berjalan sesuai skedul yang direncanakan (di simkeu) | K541: menentukan tujuan industri dan menghubungi pihak industri terkait dengan pelaksanaan kegiatan kunjungan industri
A542: 539 | B542: S-2 Teknik Elektro-2 | C542: Implementasi Kerjasama Tri Dharma dengan UTeM - S-2 Teknik Elektro - S-2 Teknik Elektro | D542: 15500000 | E542: 3 | F542: 3 | G542: LOW | I542: menurunnya : (1) Persentase mata kuliah yang menggunakan metode Team-Based Project; (2) Persentase mata kuliah yang menggunakan metode Case Method | J542: karena tidak ada acuan RPS dengan metode pembelajaran CM dan PBL, mungkin tidak ada SDM untuk menyusun RPS, sehingga mengakibatkan tidak tersedianya RPS dengan metode pembelajaran CM dan PBL
...

Sheet Target Unit
B1: REKAP IDENTIFIKASI DAN ANALISIS RISIKO SELURUH UNIT TAHUN 2025
B3: Nama Unit & Kode | C3: Usulan Kegiatan | D3: Nilai Usulan | E3: Skor Probabilitas | F3: Skor Dampak | G3: Tingkat Risiko | H3: SPIP | I3: Uraian Dampak | J3: Pernyataan Risiko | K3: Pengendalian
A4: 18 | B4: BPKU-3 | C4: Pembinaan Dan Peningkatan Kualitas Pegawai Dalam Bidang Wawasan Kebangsaan | D4: 204269000 | E4: 4 | F4: 4 | G4: HIGH | I4: Tidak terlaksananya upacara dalam rangka peringatan Dies Natalis dan hari besar nasional | J4: Karena kurangnya koordinasi internai Pokja Protokoler dengan jajaran Pimpinan, mungkin tidak terdapat informasi terkait Pembinaan dan Peningkatan Kualitas Pegawai dalam Bidang Wawasan Kebangsaan sehingga Pembinaan dan Peningkatan Kualitas Pegawai dalam Bidang Wawasan Kebangsaan tidak berjalan | K4: Melaksanakan koordinasi dengan jajaran Pimpinan terkait upacara peringatan Dies Natalis dan hari besar nasional serta mencari informasi terkait pedoman pelaksanaan upacara dengan protokol kementerian. | L4: 1
A5: 19 | B5: BPKU-6 | C5: Pameran untuk keikutsertaan Promosi | D5: 122758000 | E5: 4 | F5: 4 | G5: HIGH | I5: Tidak dapat mengikuti pameran pendidikan yang mengakibatkan Menurunnya kuantitas pendaftarSPMB | J5: Karena masih dalam penyusunan anggaran indikatif mungkin kegiatan pameran dilaksanakan di awal tahun ketika belum ada anggaran dan Anggaran belum ditetapkan sehingga Pameran Pendidikan di Wilayah Jawa Timur mengalami kesulitan | K5: Melakukan koordinasi dengan pimpinan terkait mekanisme penggunaan anggaran di awal tahun sebelum anggaran tahun berjalan ditetapkan Melakukan sosialisasi PMB melalui media sosial resmi POLINEMA, website, dan jaringan alumni sekolah | L5: 2
A6: 20 | B6: D-III Teknik Listrik-2 | C6: Kolaborasi Riset Mahasiswa dan Dosen serta pembinaan mahasiswa berprestasi - D-III Teknik Listrik | D6: 47600000 | E6: 4 | F6: 5 | G6: HIGH | I6: menurunya persentase mahasiswa yang merahih prestasi | J6: Karena Tidak ada SDM untuk koordinasi info berkala terkait lomba kepada mahasiswa mungkin minat mahasiswa untuk ikut serta lomba di tingkat nasional menjadi berkurang sehingga Tidak terdapatnya Peningkatan kualitas mahasiswa melalui keikutsertaan dalam lomba | K6: Memberikan informasi-informasi dan pemndampingan ke mahasiswa berkaitan dengan lomba-lomba | L6: 3
A7: 21 | B7: D-III Teknik Listrik-9 | C7: Pesiapan Proses Audit Mutu Internal (AMI) - D-III Teknik Listrik | D7: 17240000 | E7: 4 | F7: 5 | G7: HIGH | I7: menurunnya jumlah: (1) Jumlah mahasiswa yang terlibat dalam kegiatan penelitian; (2) Jumlah mahasiswa yang terlibat dalam kegiatan PkM; (3) Jumlah prodi terakreditasi Unggul / A. | J7: Karena Tidak adanya database untuk mendukung penyusunan Dokumen yang dibutuhkan untuk Audit Mutu Internal (AMI) mungkin tidak ada SDM untuk menyusun dokumen sehingga tidak tersedianya dokumen kelengkapan audit | K7: Dengan meunjuk tim khusus untuk melakukan pengumpulan data dukung secara terorganisir dan termonitor sehingga memudahkan penyusunan dokumen AMI serta memberikan workshop dan pendampingan dalam AMI | L7: 4
A8: 22 | B8: D-III Teknik Elektronika-1 | C8: Pelaksanaan Monitoring Evaluasi Pembelajaran Semester Ganjil - D-III Teknik Elektronika | D8: 11312000 | E8: 4 | F8: 5 | G8: HIGH | I8: Tidak adanya evaluasi proses belajar mengajar sehingga kekurangan dapat terulang di seriap tahun; Proses layanan pembelajaran kurang maksimal | J8: Karena tidak adanya koordinasi untuk menyusun panduan monitoring pelaksanaan belajar mengajar mungkin tidak ada panduan dalam melakukan monitoring proses belajar mengajar sehingga tidak terdapatnya monitoring pelaksanaan belajar mengajar, dari UTS, UAS dan yudisium. | K8: Membuat tim untuk membentuk SOP, membuat SOP untuk monitoring pembelajaran dengan pengawasan dari kps | L8: 5
A9: 23 | B9: D-III Teknik Elektronika-3 | C9: Pelaksanaan Monitoring Evaluasi Pembelajaran Semester Genap - D-III Teknik Elektronika | D9: 11312000 | E9: 4 | F9: 5 | G9: HIGH | I9: Tidak adanya evaluasi proses belajar mengajar sehingga kekurangan dapat terulang di seriap tahun; Proses layanan pembelajaran kurang maksimal | J9: Karena tidak adanya koordinasi untuk menyusun panduan monitoring pelaksanaan belajar mengajar mungkin tidak ada panduan dalam melakukan monitoring proses belajar mengajar sehingga tidak terdapatnya monitoring pelaksanaan belajar mengajar, dari UTS, UAS dan yudisium. | K9: Membuat tim untuk membentuk SOP, membuat SOP untuk monitoring pembelajaran dengan pengawasan dari kps | L9: 6
A10: 24 | B10: D-III Teknik Elektronika-4 | C10: Pembekalan Mahasiswa Untuk Peningkatan Prestasi Mahasiswa - D-III Teknik Elektronika | D10: 29470000 | E10: 4 | F10: 5 | G10: HIGH | I10: menurunya persentase mahasiswa yang meraih prestasi | J10: Karena Tidak ada SDM untuk koordinasi info berkala terkait lomba kepada mahasiswa mungkin minat mahasiswa untuk ikut serta lomba di tingkat nasional menjadi berkurang sehingga Tidak terdapatnya Peningkatan kualitas mahasiswa melalui keikutsertaan dalam lomba | K10: Memberikan informasi-informasi dan pendampingan ke mahasiswa berkaitan dengan lomba-lomba | L10: 7
A11: 25 | B11: D-III Teknik Elektronika-7 | C11: Pengadaan Bahan Habis Pakai Laboratorium dan Bengkel - D-III Teknik Elektronika | D11: 139690303 | E11: 4 | F11: 5 | G11: HIGH | I11: Menurunnya jumlah BHP | J11: Karena Tidak adanya SDM yang dapat mencari BHP Praktikum dengan kandungan TKDN dan Menyusun HPS di Prodi DIII Teknik Elektronika mungkin Proses BHP Praktikum di Prodi DIII Teknik ELektronika menjadi Terlambat sehingga Tidak tersedia BHP Praktikum yang berkualitas untuk mahasiswa Prodi DIII Teknik Elektronika. | K11: untuk menyusun HPS Minta bantuan ke Tim Teknis Perumus HPS, untuk memenuhi TKDN mengikuti data base yang ada dan minimum 40 % , dan monitoring proses pengadaan | L11: 8
A12: 193 | B12: D-III Teknik Mesin-3 | C12: Monitoring dan Supervisi Pelaksanaan Magang Industri Mahasiswa Program Studi D3 Teknik Mesin | D12: 29851000 | E12: 3 | F12: 5 | G12: MIDDLE | I12: Masukan terhadap perbaikan kurikulum serta rencana pelaksanaan magang/PKL mahasiswa dengan berlakunya kurikulum 4+1+1 (1 smstr PKL di industri) tidak maksimal tersampaikan. | J12: Karena kurangnya komunikasi dan perencanaan jadwal kunjungan yang sesuai mungkin tidak banyak perusahaan yang menerima mahasiswa PKL dapat dikunjungi untuk kegiatan monev sehingga masukan terkait pelaksanaan PKL dan masukan terhadap perbaikan kurikulum belum dapat memperoleh feedback. | K12: Perlu ditingkatkan komunikasi dan perencanaan yang matang terkait rencana monev, supervisi dan kunjungan ke industri tempat mahasiswa PKL sehingga target kegiatan dapat tercapai | L12: 9
A13: 1 | B13: D-III Teknik Telekomunikasi-1 | C13: FGD dan Inisiasi kerja sama dalam pelaksanaan PKL dan MBKM - D-III Teknik Telekomunikasi | D13: 15790000 | E13: 5 | F13: 5 | G13: EXTREME | I13: Program studi kesulitan untuk mendapatkan mitra dalam upaya meingkatkan keikutsertaan MBKM bagi mahasiswa | J13: Karena kurangnya kepercayaan industri terhadap kompetensi mahasiswa mungkin tidak banyak industri telekomuniikasi yang dapat secara langsung melibatkan mahasiswa melalui MBKM sehingga kurangnya kerjasama prodi dengan mitra untuk menunjang MBKM | K13: Membuat database PT sehingga dapat memetakan mitra/industri yang telah dan belum menyusun dokumen kerjasama dengan Polinema serta menambahkan klausul penelitian dosen dan mahasiswa dalam dokumen kerjasama yang telah/akan dibuat | L13: 10
A14: 2 | B14: D-III Teknik Telekomunikasi-2 | C14: FGD dan Inisiasi Kerjasama dengan Kampus LN - D-III Teknik Telekomunikasi | D14: 8320000 | E14: 5 | F14: 5 | G14: EXTREME | I14: Program studi kesulitan untuk mendapatkan mitra dalam upaya meingkatkan keikutsertaan MBKM bagi mahasiswa | J14: Karena kurangnya kepercayaan industri terhadap kompetensi mahasiswa mungkin tidak banyak industri telekomuniikasi yang dapat secara langsung melibatkan mahasiswa melalui MBKM sehingga kurangnya kerjasama prodi dengan mitra untuk menunjang MBKM | K14: Membuat database PT sehingga dapat memetakan mitra/industri yang telah dan belum menyusun dokumen kerjasama dengan Polinema serta menambahkan klausul penelitian dosen dan mahasiswa dalam dokumen kerjasama yang telah/akan dibuat | L14: 11
A15: 26 | B15: D-III Teknik Telekomunikasi-5 | C15: Pemeliharaan Peralatan dan Mesin | D15: 45000000 | E15: 4 | F15: 5 | G15: HIGH | I15: Menurunnya jumlah alat/fasilitas/prasarana yang telah dipelihara dan berfungsi dengan baik | J15: Karena tidak ada database penyedia jasa pemeliharaan dan perawatan sarana prasarana pembelajaran mungkin tidak adanya pemetaan penyedia jasa pemeliharaan dan perawatan sarana prasarana yang baik sehingga tidak terlaksana pemeliharaan dan perawatan sarana dan prasarana pembelajaran | K15: 1. Membuat database penyedia jasa perawatan 2. Pemilihan penyedia jasa yang sesuai 3. Koordinasi dengan penyedia jasa untuk jadwal pelaksanaan perawatan 4. Melakukan pemantauan, perawatan, dan perbaikan alat dan mesin secara rutin | L15: 12
... A36: 9 | B36: D-IV Usaha Perjalanan Wisata-4 | C36: Peningkatan Kerjasama Program Studi Melalui Praktikum Mahasiswa Pada Mata Kuliah Akomodasi Perhotelan Dan Dan Restoran Ke Hotel Grand Mercure Malang Mirama - D-IV Usaha Perjalanan Wisata | D36: 4095000 | E36: 5 | F36: 5 | G36: EXTREME | I36: proses kegiatan praktikum tidak maksimal dan peserta tidak mendapatkan ilmu yang bisa digunakan pada dunia kerja | J36: karena tidak ada mahasiswa D4 UPW yang melakukan praktikum mahasiswa pada mata kuliah Akomodasi Perhotelan dan Restoran di industri secara riil mungkin karena tidak adanya praktisi dan pendamping minat kegiatan mahasiswa sehingga praktikum tersebut tidak berjalan | K36: melakukan persiapan secara matang untuk mencari narasumber yang sesuai dengan tema dan memiliki pengalaman menjadi pendamping pada program praktikum atau sejenis | L36: 33
A37: 10 | B37: D-IV Usaha Perjalanan Wisata-6 | C37: Workshop Ticketing and Reservation System - D-IV Usaha Perjalanan Wisata | D37: 4595000 | E37: 5 | F37: 5 | G37: EXTREME | J37: Karena terbatasnya industri atau institusi yang membuka program pelatihan ticketing dan reservation yang selaras dengan kebutuhan prodi D4 UPW dan mahasiswa tidak menyesuaikan kurikulum , mungkin karena terhambatnya proses penyusunan pedoman kurikulum khususnya ticketing dan reservation sehingga Workshop Ticketing and Reservation System - D-IV Usaha Perjalanan Wisata tidak berjalan dengan sesuai seperti yang diharapkan | K37: Sosialisasi kurikulum MK Ticketing dan Reservation dengan metode PBL sebelum kegiatan kepada seluruh dosen homebase D4 UPW | L37: 34
A38: 11 | B38: D-IV Usaha Perjalanan Wisata-7 | C38: Forum Group Discussion Tentang Penyusunan Kurikulum Berbasis OBE dengan Industri - D-IV Usaha Perjalanan Wisata | D38: 6455000 | E38: 5 | F38: 5 | G38: EXTREME | I38: Lamanya waktu yang diperlukan untuk telaah dan persiapan draft bahan ajar berbasis OBE | J38: Karena terbatasnya industri yang membuka program MBKM yang selaras dengan Prodi D4 UPW dan mahasiswa tidak menyesuaikan kurikulum dalam mengajukan MBKM mungkin karena terhambatnya proses penyusunan pedoman kurikulum berbasis OBE dengan industri di kantor pusat sehingga FGD tentang Penyusunan Kurikulum Berbasis OBE dengan Industri D-IV Usaha Perjalanan Wisata tidak berjalan sesuai yg seperti diharapkan | K38: Sosialisasi pedoman pembelajaran berbasis OBE sebelum kegiatan kepada seluruh dosen homebase D$ UPW | L38: 35
A39: 12 | B39: Jurusan Teknik Elektro-3 | C39: Inisiasi Kerjasama Dengan Mitra Potensial Dalam Bentuk Focus Group Discussion di Jurusan Teknik Elektro | D39: 17500000 | E39: 5 | F39: 5 | G39: EXTREME | I39: Jurusan Teknik Elektro tidak memiliki mitra untuk dapat meningkatkan kerjasama industri | J39: Karena kurangnya kepercayaan industri terhadap kompetensi Jurusan Teknik Elektro mungkin tidak banyak industri telekomuniikasi yang dapat secara langsung menjalin kerjasama melalui sehingga kurangnya kerjasama prodi dengan mitra untuk menunjang MBKM | K39: Membuat database PT sehingga dapat memetakan mana yang belum MoU dan yang sudah selain itu membuat perjanjian ditambahkan dengan penelitian dosen dan mahasiswa | L39: 36
A40: 112 | B40: P3M-12 | C40: PPM DIPA KOMPETISI 2025 - P3M | D40: 2530154350 | E40: 4 | F40: 5 | G40: HIGH | I40: Menggangu ketercapaian kinerja dosen dan IKU Polinema | J40: KARENA padatnya agenda pada Unit P3M Polinema MUNGKIN sosialisasi kegiatan pengabdian pada masyarakat tidak berjalan efektif SEHINGGA kegiatan PPM DIPA Kompetisi 2025 - P3M tidak mencapai target | K40: Perlu dilakukan penyusunan panduan dan skema pengabdian sebagai petunjuk teknis pelaksanaan. Perlu dilakukan sosialisasi panduan dan penentuan penjadwalan seleksi hingga pelaporan pelaksanaan kepada seluruh civitas akademika Polinema. Perlu dilakukannya monitoring dan koordinasi pelaksanaan kegiatan sehingga luaran pengabdian dapat tercapai | L40: 37
A41: 13 | B41: P3M-15 | C41: PENELITIAN DIPA KOMPETISI 2025 - P3M | D41: 5440155000 | E41: 5 | F41: 5 | G41: EXTREME | I41: Menggangu ketercapaian kinerja dosen dan IKU Polinema | J41: KARENA terlambat dalam menentukan skema penelitian MUNGKIN sosialisasi perubahan aturan terlambat disampaikan kepada peneliti SEHINGGA Penelitian DIPA KOMPTESI 2025 P3M tidak dapat dilaksanakan | K41: Perlu dilakukan penyusunan panduan dan skema penelitian sebagai petunjuk teknis pelaksanaan. Perlu dilakukan sosialisasi panduan dan penentuan penjadwalan seleksi hingga pelaporan pelaksanaan kepada seluruh civitas akademika Polinema. Perlu dilakukannya monitoring dan koordinasi pelaksanaan kegiatan sehingga luaran penelitian dapat tercapai | L41: 38
A42: 505 | B42: PSDKU Kota Kediri-20 | C42: GAJI DAN TUNJANGAN TENAGA KEPENDIDIKAN NON PNS | D42: 1946143150 | E42: 2 | F42: 4 | G42: LOW | I42: 1. keterlambatan pembayaran gaji dan tunjangan tenaga kependidikan 2. Penurunan produktivitas kinerja tenaga kependidikan 3. Proses administrasi perkantoran dan penunjang akademik tidak berjalan dengan lancar | J42: Karena adanya keterlambatan pengajuan pembayaran gaji dan tunjangan tenaga kependidikan mungkin pembayaran gaji dan tunjangan tenaga kependidikan tertunda sehingga menyebabkan penurunan kinerja tenaga kependidikan | K42: Untuk mengatasi risiko yang mungkin terjadi maka cara mengendalikan dampaknya adalah dengan memberikan pembayaran gaji sesuai dengan tanggal yang sudah ditetapkan | L42: 39
A43: 507 | B43: PSDKU Kota Kediri-22 | C43: PEMBAYARAN GAJI DAN TUNJANGAN ASN | D43: 3698315264 | E43: 2 | F43: 4 | G43: LOW | I43: 1. keterlambatan pembayaran gaji dan tunjangan PNS dan PPPK 2. Penurunan produktivitas kinerja PNS dan PPPK 3. Proses administrasi perkantoran dan penunjang akademik tidak berjalan dengan lancar | J43: Karena adanya keterlambatan pengajuan pembayaran gaji dan tunjangan PNS dan PPPK mungkin pembayaran gaji dan tunjangan PNS dan PPPK tertunda sehingga menyebabkan penurunan kinerja PNS dan PPPK | K43: Untuk mengatasi risiko yang mungkin terjadi maka cara mengendalikan dampaknya adalah dengan memberikan pembayaran gaji sesuai dengan tanggal yang sudah ditetapkan | L43: 40
A44: 496 | B44: PSDKU Kota Kediri-5 | C44: BIAYA JASA KEAMANAN, CLEANING SERVICE DAN GARDENER - PSDKU Kota Kediri | D44: 1646400000 | E44: 2 | F44: 4 | G44: LOW | I44: 1. Gaji dan fasilitas tenaga outsourcing berubah setiap tahun 2. Kinerja pegawai outsourcing di bawah standard yang diharapkan institusi 3. Kenyamanan dan kemanan lingkungan kampus dan perkantoran tidak optimal 4. Memerlukan waktu untuk beradaptasi kembali antara instansi PSDKU Kediri dan karyawan outsourcing dengan peraturan vendor baru | J44: Karena sistem pengadaan tenaga outsourcing dengan sistem lelang setiap tahunnya sehingga mungkin gaji dan fasilitas yang diterima tenaga kerja outsourcing berubah - ubah sesuai dengan ketentuan vendor yang memenangkan lelang kontrak, sehingga jika terjadi penurunan gaji dan fasilitas menyebabkan turunnya kinerja tenaga kerja outsourcing | K44: Untuk mengatasi risiko yang mungkin terjadi maka cara mengendalikan dampaknya adalah dengan melakukan koordinasi dengan vendor pemenang lelang untuk memberikan upah sesuai yang berlaku dengan tidak merugikan vendor | L44: 41
A45: 511 | B45: PSDKU Kota Lumajang-5 | C45: Belanja Operasional Penunjang Layanan Pendidikan (HIBAH dan PNBP) | D45: 1761377200 | E45: 2 | F45: 5 | G45: LOW | I45: 1. Layanan Pendidikan Terganggu, Jika dana operasional tidak tersedia, berbagai layanan pendidikan seperti pemeliharaan fasilitas, pengadaan alat pendukung, dan kegiatan akademik bisa terhambat. 2. Menurunnya Kualitas Pendidikan dan Layanan, Tanpa anggaran yang cukup, institusi mungkin kesulitan memberikan layanan yang optimal kepada mahasiswa dan tenaga pendidik. 3. Terhambatnya Kegiatan Akademik dan Kemahasiswaan, Jika dana operasional mencakup kegiatan mahasiswa, maka berbagai program seperti seminar, pelatihan, dan kegiatan ekstrakurikuler bisa mengalami hambatan atau dibatalkan. 4. Risiko Ketidakpatuhan Terhadap Peraturan Keuangan, Jika belanja operasional tidak dilaksanakan sesuai dengan peraturan yang berlaku, bisa timbul masalah administrasi atau bahkan sanksi dari pihak terkait. | J45: Karena Tidak memiliki jumlah tim pelaksana yang memenuhi untuk mengatasi banyaknya penanganan pengajuan realisasi GU/TUP, Mungkin menyebabkan Tidak ada Pemetaan program Rencana Anggaran Biaya yang bersumber dari Hibah Pemerintah Kabupaten Lumajang, Sehingga kegiatan Belanja Operasional Penunjang Layanan Pendidikan (HIBAH dan PNBP) tidak dapat dilaksanakan. | K45: Melakukan Pembayaran Secara Rutin dan berkala sesuai SBM dan Kepatiuhan terhadapa aturan yang berlaku sesuai target capaian Unit Kerja, melakukan koordinasi dengan pihak terkait agar pencairan dana bisa dipercepat, melakukan perencanaan keuangan yang lebih matang, serta memastikan bahwa regulasi dan persyaratan administrasi terpenuhi agar belanja operasional dapat segera direalisasikan. | L45: 42
A46: 553 | B46: UPA Bahasa-5 | C46: UJIAN TOEIC - MALA DAN IISMA 2025 - UPA BAHASA | D46: 1506265000 | E46: 2 | F46: 5 | G46: LOW | I46: 1. Kegiatan tidak terlaksana sehingga menyebabkan kerugian baik moril maupun materiil. | J46: Karena kurang adanya koordinasi dengan masing-masing jurusan baik di kampus utama maupun PSDKU terkait sosialisasi TOEIC untuk MALA, dan mungkin karena tidak ada sosialisasi terstruktur terkait TOEIC kepada MALA sehingga kegiatan ujian TOEIC MALA tidak berjalan. | K46: Untuk mengatasi resiko yang mungkin terjadi, maka cara mengendalikan dampaknya adalah: 1) melakukan koordinasi dengan semua jurusan baik di kampus utama maupun PSDKU; 2) memberikan sosialisasi mengenai ujian TOEIC dan memberikan kesempatan mahasiswa tingkat akhir mempersiapkan diri secara mandiri dengan menyediakan soal-soal latihan TOEIC dengan menggunakan platform seperti google classroom atau moodle. | L46: 43
A47: 15 | B47: UPA Pengembangan Karir dan Kewirausahaan-10 | C47: Program Mahasiswa Wirausaha (PMW) Polinema 2025 - UPA Pengembangan Karir dan Kewirausahaan | D47: 302568000 | E47: 5 | F47: 5 | G47: EXTREME | I47: Karena KETERLAMBATAN DAN SULITNYA PROSES PENCAIRAN BANTUAN MODAL USAHA , sehingga menyebabkan resiko sangat terlambat dalam proses pendampingan dan produksi, yang mengakibatkan mundurnya jadwal kegiatan lainnya sebagai rangkaian kegiatan PMW. ada beberapa kegiatan lain yang pelaksanaan nya hanya bisa dilakukan setelah tenant PMW berjalan proses produksinya, sehingga jika pencairan modal usaha ini terlambata akan menghambat pelaksanaan kegiatan lainnya. perlu di pahami bahwa wirausaha adalah menjalankan usaha yang membutuhkan modal untuk proses produksinya. periode waktu usaha yang seharusnya 1 tahun juga sangat terbatas, karena efektif operasional usahanya hanya 6 bulan (jika pencairan bantuan modal di bulan mei 2025). hal ini sebenar nya kurang efektif untuk progres sebuah usaha. oleh karena itu kami berharap bantuan untuk ketepatan jawal pelaksanaan program. | J47: Karena KETERLAMBATAN DAN SULITNYA PROSES PENCAIRAN BANTUAN MODAL USAHA , sehingga menyebabkan resiko sangat terlambat dalam proses pendampingan dan produksi, yang mengakibatkan mundurnya jadwal kegiatan lainnya sebagai rangkaian kegiatan PMW. | K47: 1. penjadwalan dan pelaksanaan kegiatan sesuai dengan time line yang sudah di tetapkan. 2. koordinasi dengan bagian keuangan dan tim kerja terkait ketepatan waktu pencairan bantuan modal usaha mahasiswa. 3. komunikasi yang baik agar pelaksanaan kegiatan bisa dilakukan dengan baik, efektif, tepat waktu , dan memberikan manfaat bagi mahasiswa wirausaha. | L47: 44
A48: 14 | B48: UPA Pengembangan Karir dan Kewirausahaan-4 | C48: INKUBASI WIRAUSAHA MAHASISWA 2025 - UPA Pengembangan Karir dan Kewirausahaan | D48: 77080000 | E48: 5 | F48: 5 | G48: EXTREME | I48: terjadi kemunduran pelaksanaan kegiatan penampingan usaha dari tenant inkubasi. | J48: karena adanya keterlambatan pencairan bantuan modal usaha dan tidak tepat waktu, sehingga menyebabkan kendala di keseluruhan proses pendampingan terutama mundurnya jadwal pelaksanaan kegiatan. | K48: membuat jadwal pelaksanaanan kegiatan, dan kepatuhan terhadap jadwal yang di buat. pencairan modal usaha tepat waktu sehingga membantu proses kelancaran pendampingan dan kegiatan produksi mahasiswa wirausaha. | L48: 45
A49: 592 | B49: WADIR I-7 | C49: Peningkatan Kuantitas dan Kualitas Lulusan melalui Kegiatan Wisuda - WADIR I | D49: 3618671150 | E49: 2 | F49: 5 | G49: LOW | I49: Bentuk dukungan kepada lulusan dan menggeser status menjadi alumni | J49: Karena jumlah mahasiswa yang lulus di tahun berjalan tidak menentu mungkin akan kesulitan menyesuaikan dengan jadwal yang sudah direncanakan sehingga kegiatan Peningkatan Kualitas Lulusan melalui Kegaiatan Wisuda. - PEMBANTU DIREKTUR I tidak bisa dijalankan. | K49: melibatkan akademik prodi dan akademik pusat serta seluruh civitas untuk bertanggung jawab terhadap kelulusan | L49: 46
... A75: 16 | B75: WADIR II-10 | C75: PEMBANGUNAN GEDUNG DAN BANGUNAN PENDUKUNG PEMBELAJARAN - BLU | D75: 40556300000 | E75: 5 | F75: 5 | G75: EXTREME | I75: Melakukan persiapan data dukung tender secara lengkap dan lebih awal, dan pendampingan proses oleh BPKP Jawa Timur dan Kejaksaan Tinggi Negeri | J75: Karena Data dukung penting untuk pengadaan tidak segera tersedia mungkin Kelengkapan berkas pengadaan terlambat sehingga Pembangunan Gedung dan Bangunan Pendukung Pembelajaran tidak selesai. | K75: Adanya pendampingan dari pihak BPKP Jawa Timur dan Kejaksaan Tinggi Negeri agar pembangunan gedung dan bangunan pendukung pembelajaran dapat selesai tepat waktu. | L75: 72

Sheet Panduan
B1: PANDUAN PENGISIAN
B2: LEMBAR MONITORING DAN EVALUASI MANAJAMENEN RISIKO UNIT
B3: SATUAN PENGAWAS INTERNAL POLITEKNIK NEGERI MALANG
B4: TAHUN 2025
B6: 1. | C6: Pastikan Unit dan No Kegiatan yang akan di reviu sesuai dengan Sheet Distribusi Unit
B7: 2. | C7: Apabila Kegiatan tersebut sudah selesai dilaksanakan, tentukan kegiatan lain unit tersebut yang belum di laksanakan dengan pertimbangan Level Risiko pada Sheet By Level, dengan cara Filter Nama Unit pada Kolom Nama Unit dan Kode, kemudian Filter lagi dengan Tingkat Risiko
B8: 3. | C8: Pilih Nama Reviuer pada Kolom Pemonev
B9: 4. | C9: Entry No Kegiatan yang akan di reviu pada Sheet Lembar Monitoring, mulai dari No Kegiatan 1 - 9 pada baris 7 sheet tersebut
B10: 5. | C10: Pilih Mitigasi Risiko yang diambil oleh Unit Kolom Mitigasi Risiko
C11: - Menerima Risiko
C12: - Membagi Risiko
C13: - Melimpahkan Risiko
B14: 6. | C14: Isikan Mitigasi Risiko yang dipilih Unit dengan ketentuan:
C15: - Jika Membagi Risiko atau Melimpahkan Risiko
C16: ==> Isikan Nama Unit Penerima Risiko (bisa 1 unit atau lebih) pada Kolom Unit Penerima Risiko
C17: - Jika Menerima Risiko
C18: ==> Isikan Blank Cell pada Kolom Unit Penerima Risiko
B19: 7. | C19: Isi Kolom Status Konfirmasi yang sesuai jika:
C20: - Menerima Risiko ==> Status Konfirmasi Blank Cell
C21: - Membagi atau Melimpahkan Risiko ==> Konfirmasi Status (Sudah Konfirmasi / Belum Konfirmasi) Unit Penerima Risiko
B22: 8. | C22: Pilih Risiko Residual sebagai dampak Mitigasi tersebut pada langkah 4
C23: - Extreme
C24: - High
C25: - Middle
C26: - Low
C27: - Very Low
B28: 9. | C28: Beri Komentar pada kolom Komentar:
C29: - Bagaimana mereka memitigasi Risiko kegiatan
C30: - Bagaimana efek mitigasi risiko sehingga Residual Risiko berubah turun atau naik
C31: - Komentar lainnya
B32: 10. | C32: Entry nama lengkap Wakil Unit pada tempatnya
B33: 11. | C33: Lanjutkan cara yang sama pada kegiatan yang lain.
B34: 12. | C34: Klik gambar Dokumen ( ) di samping untuk menuju pada kegiatan selanjutnya. Warna kuning menunjukkan sedang berada pada kegiatan tersebut
